<?xml version="1.0" encoding="utf-8"?>
<!-- This URDF was automatically created by SolidWorks to URDF Exporter! Originally created by Stephen Brawner (brawner@gmail.com) 
     Commit Version: 1.6.0-4-g7f85cfe  Build Version: 1.6.7995.38578
     For more information, please see http://wiki.ros.org/sw_urdf_exporter -->
<robot name="a1_neck" xmlns:xacro="http://ros.org/wiki/xacro">

    <xacro:property name="damping" value="3.121E-6"/>
    <xacro:property name="friction" value="2.369E-4"/>

  <xacro:macro name="a1_neck" params="parent *origin">

    <!-- connect external origin with local root link -->
    <joint name="a1_neck_joint" type="fixed">
      <xacro:insert_block name="origin" />
      <parent link="${parent}"/>
      <child link="servo_link_1" />
    </joint>

    <link name="servo_link_1">
      <inertial>
        <origin
          xyz="0.012635 0.0 0.0011677"
          rpy="0 0 0" />
        <mass
          value="0.042672" />
        <inertia
          ixx="3.5455E-06"
          ixy="-9.8833E-12"
          ixz="-3.2724E-08"
          iyy="8.6941E-06"
          iyz="9.7525E-14"
          izz="9.9716E-06" />
      </inertial>
      <visual>
        <origin
          xyz="0 0 0"
          rpy="0 0 0" />
        <geometry>
          <mesh
            filename="package://a1_neck_description/meshes/servo_link_1.STL" />
        </geometry>
        <material
          name="">
          <color
            rgba="0.50196 0.50196 0.50196 1" />
        </material>
      </visual>
      <collision>
        <origin
          xyz="0.013 0 0.002"
          rpy="0 0 0" />
            <geometry>
                <box size=".05 .028 .033"/>
            </geometry>
            <material name="">
              <color rgba="1. 0. 0. 1" />
            </material>
      </collision>
    </link>
    <link
      name="servo_link_2">
      <inertial>
        <origin
          xyz="-0.0013648 0.016 0.0011677"
          rpy="0 0 0" />
        <mass
          value="0.042672" />
        <inertia
          ixx="3.5455E-06"
          ixy="-9.8831E-12"
          ixz="-3.2724E-08"
          iyy="8.6941E-06"
          iyz="9.758E-14"
          izz="9.9716E-06" />
      </inertial>
      <visual>
        <origin
          xyz="0 0 0"
          rpy="0 0 0" />
        <geometry>
          <mesh
            filename="package://a1_neck_description/meshes/servo_link_2.STL" />
        </geometry>
        <material
          name="">
          <color
            rgba="0.50196 0.50196 0.50196 1" />
        </material>
      </visual>
      <collision>
        <origin
          xyz="0 0.016 0"
          rpy="0 0 0" />
            <geometry>
                <box size=".055 .028 .033"/>
            </geometry>
      </collision>
    </link>
    <joint
      name="servo1_to_servo2"
      type="revolute">
      <origin
        xyz="0 -0.021 0"
        rpy="-3.1416 0 0" />
      <parent
        link="servo_link_1" />
      <child
        link="servo_link_2" />
      <axis
        xyz="0 1 0" />
      <limit
        lower="-1.57"
        upper="1.57"
        effort="10"
        velocity="6" />
      <dynamics damping="${damping}" friction="${friction}"/>
    </joint>
    <link name="camera_mount_link"/>
    <joint
      name="servo2_to_camera"
      type="revolute">
      <origin
        xyz="0 0.016 0.021"
        rpy="0 0 3.1415" />
      <parent
        link="servo_link_2" />
      <child
        link="camera_mount_link" />
      <axis
        xyz="0 0 -1" />
      <limit
        lower="-1.57"
        upper="1.57"
        effort="10"
        velocity="6" />
      <dynamics damping="${damping}" friction="${friction}"/>
    </joint>
  </xacro:macro>
</robot>